<?xml version="1.0"?>
<robot name="xy_unilivers">

  <link name="base">
    <visual>
      <geometry>
        <box size="0.80 0.10 0.22" />
      </geometry>
      <origin xyz="0.3 0 0.08" />
      <material name="blue">
        <color rgba="0.0 0.0 1.0 0.5" />
      </material>
    </visual>
  </link>

  <joint name="base_to_charriot" type="prismatic">
    <parent link="base" />
    <child link="Charriot" />
    <origin xyz="0 0 0" rpy="0 0 0" />
    <axis xyz="1 0 0" />
    <limit lower="0.02" upper="0.2" effort="1000" velocity="0.5" />
  </joint>
  <link name="Charriot">
    <visual>
      <geometry>
        <box size="0.150 0.150 0.013" />
      </geometry>
      <origin xyz="0.075 0.0 0.0" />
      <material name="white">
        <color rgba="1.0 1.0 1.0 0.8" />
      </material>
    </visual>
  </link>

</robot>
